<?xml version="1.0" encoding="utf-8"?>
<!-- This URDF was automatically created by SolidWorks to URDF Exporter! Originally created by Stephen Brawner (brawner@gmail.com) 
     Commit Version: 1.6.0-4-g7f85cfe  Build Version: 1.6.7995.38578
     For more information, please see http://wiki.ros.org/sw_urdf_exporter -->
<robot
  name="Digital_twin_lab-2">
  <link
    name="base_link">
    <inertial>
      <origin
        xyz="0.906506607373006 -1.11864782435858 -0.0645903984698896"
        rpy="0 0 0" />
      <mass
        value="199.387495804579" />
      <inertia
        ixx="10.5663994006333"
        ixy="1.27796504504511E-10"
        ixz="2.82196582358364E-10"
        iyy="42.9922092220749"
        iyz="7.13111678705662E-12"
        izz="52.3668102113991" />
    </inertial>
    <visual>
      <origin
        xyz="0 0 0"
        rpy="0 0 0" />
      <geometry>
        <mesh
          filename="package://Digital_twin_lab-2/meshes/base_link.STL" />
      </geometry>
      <material
        name="">
        <color
          rgba="0.752941176470588 0.752941176470588 0.752941176470588 1" />
      </material>
    </visual>
    <collision>
      <origin
        xyz="0 0 0"
        rpy="0 0 0" />
      <geometry>
        <mesh
          filename="package://Digital_twin_lab-2/meshes/base_link.STL" />
      </geometry>
    </collision>
  </link>
  <link
    name="SlideRail">
    <inertial>
      <origin
        xyz="0.866665161394367 0.200928921167978 -1.43995243789587"
        rpy="0 0 0" />
      <mass
        value="9.10141973800531" />
      <inertia
        ixx="7.2200527077908"
        ixy="6.58677957674569E-06"
        ixz="2.47766910422405E-07"
        iyy="7.22100259175683"
        iyz="-2.22783563372611E-08"
        izz="0.00462584403154548" />
    </inertial>
    <visual>
      <origin
        xyz="0 0 0"
        rpy="0 0 0" />
      <geometry>
        <mesh
          filename="package://Digital_twin_lab-2/meshes/SlideRail.STL" />
      </geometry>
      <material
        name="">
        <color
          rgba="0.752941176470588 0.752941176470588 0.752941176470588 1" />
      </material>
    </visual>
    <collision>
      <origin
        xyz="0 0 0"
        rpy="0 0 0" />
      <geometry>
        <mesh
          filename="package://Digital_twin_lab-2/meshes/SlideRail.STL" />
      </geometry>
    </collision>
  </link>
  <joint
    name="SlideRail-j"
    type="fixed">
    <origin
      xyz="2.2044 -0.31797 0.29704"
      rpy="-1.5708 0 -1.5708" />
    <parent
      link="base_link" />
    <child
      link="SlideRail" />
    <axis
      xyz="0 0 0" />
  </joint>
  <link
    name="RobotBase">
    <inertial>
      <origin
        xyz="-0.00404752744529402 0.0637675180517647 0.0724834929980328"
        rpy="0 0 0" />
      <mass
        value="1.14266042467365" />
      <inertia
        ixx="0.00151841225352524"
        ixy="1.49355567893237E-06"
        ixz="1.73102113053107E-06"
        iyy="0.00274882213327468"
        iyz="-3.14623443477032E-07"
        izz="0.00136637515019257" />
    </inertial>
    <visual>
      <origin
        xyz="0 0 0"
        rpy="0 0 0" />
      <geometry>
        <mesh
          filename="package://Digital_twin_lab-2/meshes/RobotBase.STL" />
      </geometry>
      <material
        name="">
        <color
          rgba="1 1 1 1" />
      </material>
    </visual>
    <collision>
      <origin
        xyz="0 0 0"
        rpy="0 0 0" />
      <geometry>
        <mesh
          filename="package://Digital_twin_lab-2/meshes/RobotBase.STL" />
      </geometry>
    </collision>
  </link>
  <joint
    name="RobotBase-j"
    type="prismatic">
    <origin
      xyz="0.8613 0.2115 -2.8602"
      rpy="3.1416 0 0" />
    <parent
      link="SlideRail" />
    <child
      link="RobotBase" />
    <axis
      xyz="0 0 1" />
    <limit
      lower="-4"
      upper="4"
      effort="0"
      velocity="0" />
  </joint>
  <link
    name="arm1">
    <inertial>
      <origin
        xyz="0.00685553937981664 0.113055754742752 -0.0319364397196832"
        rpy="0 0 0" />
      <mass
        value="0.675270731859806" />
      <inertia
        ixx="0.00202049846045333"
        ixy="2.1595440070163E-06"
        ixz="-1.28544229522281E-05"
        iyy="0.00191415489362235"
        iyz="-0.000448958622264817"
        izz="0.000845244420385655" />
    </inertial>
    <visual>
      <origin
        xyz="0 0 0"
        rpy="0 0 0" />
      <geometry>
        <mesh
          filename="package://Digital_twin_lab-2/meshes/arm1.STL" />
      </geometry>
      <material
        name="">
        <color
          rgba="0.792156862745098 0.819607843137255 0.933333333333333 1" />
      </material>
    </visual>
    <collision>
      <origin
        xyz="0 0 0"
        rpy="0 0 0" />
      <geometry>
        <mesh
          filename="package://Digital_twin_lab-2/meshes/arm1.STL" />
      </geometry>
    </collision>
  </link>
  <joint
    name="arm1-j"
    type="revolute">
    <origin
      xyz="-0.0041396 0.095257 0.072641"
      rpy="0 0 0" />
    <parent
      link="RobotBase" />
    <child
      link="arm1" />
    <axis
      xyz="0 1 0" />
    <limit
      lower="-175"
      upper="180"
      effort="0"
      velocity="0" />
  </joint>
  <link
    name="arm2">
    <inertial>
      <origin
        xyz="0.00934921836749636 0.050968485668847 -6.27171795658521E-06"
        rpy="0 0 0" />
      <mass
        value="0.271676192230461" />
      <inertia
        ixx="0.00133562993036315"
        ixy="-1.01591687129694E-08"
        ixz="1.05560141265999E-11"
        iyy="0.000109874068209674"
        iyz="-8.79700367721104E-09"
        izz="0.0012911750222442" />
    </inertial>
    <visual>
      <origin
        xyz="0 0 0"
        rpy="0 0 0" />
      <geometry>
        <mesh
          filename="package://Digital_twin_lab-2/meshes/arm2.STL" />
      </geometry>
      <material
        name="">
        <color
          rgba="0.792156862745098 0.819607843137255 0.933333333333333 1" />
      </material>
    </visual>
    <collision>
      <origin
        xyz="0 0 0"
        rpy="0 0 0" />
      <geometry>
        <mesh
          filename="package://Digital_twin_lab-2/meshes/arm2.STL" />
      </geometry>
    </collision>
  </link>
  <joint
    name="arm2-j"
    type="revolute">
    <origin
      xyz="0 0.19707 0.095476"
      rpy="1.5708 0 0" />
    <parent
      link="arm1" />
    <child
      link="arm2" />
    <axis
      xyz="1 0 0" />
    <limit
      lower="-90"
      upper="180"
      effort="0"
      velocity="0" />
  </joint>
  <link
    name="arm3">
    <inertial>
      <origin
        xyz="-0.00340437043110531 -5.11241685569042E-06 0.0310100738015653"
        rpy="0 0 0" />
      <mass
        value="0.293438315475955" />
      <inertia
        ixx="0.000573707689974129"
        ixy="-3.2473057372314E-09"
        ixz="2.23455758974529E-06"
        iyy="0.000542174612167973"
        iyz="3.78430629941778E-09"
        izz="6.73628408544744E-05" />
    </inertial>
    <visual>
      <origin
        xyz="0 0 0"
        rpy="0 0 0" />
      <geometry>
        <mesh
          filename="package://Digital_twin_lab-2/meshes/arm3.STL" />
      </geometry>
      <material
        name="">
        <color
          rgba="0.792156862745098 0.819607843137255 0.933333333333333 1" />
      </material>
    </visual>
    <collision>
      <origin
        xyz="0 0 0"
        rpy="0 0 0" />
      <geometry>
        <mesh
          filename="package://Digital_twin_lab-2/meshes/arm3.STL" />
      </geometry>
    </collision>
  </link>
  <joint
    name="arm3-j"
    type="revolute">
    <origin
      xyz="0 0.2032 0"
      rpy="-1.5708 0 0" />
    <parent
      link="arm2" />
    <child
      link="arm3" />
    <axis
      xyz="1 0 0" />
    <limit
      lower="-142"
      upper="142"
      effort="0"
      velocity="0" />
  </joint>
  <link
    name="wrist1">
    <inertial>
      <origin
        xyz="-5.1119E-05 5.5335E-07 3.3649E-05"
        rpy="0 0 0" />
      <mass
        value="0.019467" />
      <inertia
        ixx="1.9403E-06"
        ixy="-2.6056E-12"
        ixz="3.726E-11"
        iyy="5.5184E-06"
        iyz="1.4992E-08"
        izz="6.4217E-06" />
    </inertial>
    <visual>
      <origin
        xyz="0 0 0"
        rpy="0 0 0" />
      <geometry>
        <mesh
          filename="package://Digital_twin_lab-2/meshes/wrist1.STL" />
      </geometry>
      <material
        name="">
        <color
          rgba="0.79216 0.81961 0.93333 1" />
      </material>
    </visual>
    <collision>
      <origin
        xyz="0 0 0"
        rpy="0 0 0" />
      <geometry>
        <mesh
          filename="package://Digital_twin_lab-2/meshes/wrist1.STL" />
      </geometry>
    </collision>
  </link>
  <joint
    name="wrist1-j"
    type="revolute">
    <origin
      xyz="0 0 0.1524"
      rpy="0.016592 0 -3.1416" />
    <parent
      link="arm3" />
    <child
      link="wrist1" />
    <axis
      xyz="1 0 0" />
    <limit
      lower="-135"
      upper="135"
      effort="0"
      velocity="0" />
  </joint>
  <link
    name="wrist2">
    <inertial>
      <origin
        xyz="-9.74873192043368E-05 0.00113235857781457 0.0343595995073909"
        rpy="0 0 0" />
      <mass
        value="0.0107694009383611" />
      <inertia
        ixx="3.78310186730164E-06"
        ixy="-6.90021934175136E-13"
        ixz="-2.09501677057643E-12"
        iyy="3.85897258651782E-06"
        iyz="-1.13747753917068E-07"
        izz="8.95604606902071E-07" />
    </inertial>
    <visual>
      <origin
        xyz="0 0 0"
        rpy="0 0 0" />
      <geometry>
        <mesh
          filename="package://Digital_twin_lab-2/meshes/wrist2.STL" />
      </geometry>
      <material
        name="">
        <color
          rgba="0.792156862745098 0.819607843137255 0.933333333333333 1" />
      </material>
    </visual>
    <collision>
      <origin
        xyz="0 0 0"
        rpy="0 0 0" />
      <geometry>
        <mesh
          filename="package://Digital_twin_lab-2/meshes/wrist2.STL" />
      </geometry>
    </collision>
  </link>
  <joint
    name="wrist2-j"
    type="revolute">
    <origin
      xyz="0 0 0"
      rpy="0 0 0" />
    <parent
      link="wrist1" />
    <child
      link="wrist2" />
    <axis
      xyz="0 0.016592 0.99986" />
    <limit
      lower="360"
      upper="350"
      effort="0"
      velocity="0" />
  </joint>
  <link
    name="gripper">
    <inertial>
      <origin
        xyz="1.10282947725766 -0.0701169459120974 2.78560724279916"
        rpy="0 0 0" />
      <mass
        value="1.24999135313939" />
      <inertia
        ixx="0.000340540281739785"
        ixy="3.14164094804625E-06"
        ixz="-1.52074431963212E-07"
        iyy="0.000270267274639191"
        iyz="1.46504278799866E-06"
        izz="0.000269224814017906" />
    </inertial>
    <visual>
      <origin
        xyz="0 0 0"
        rpy="0 0 0" />
      <geometry>
        <mesh
          filename="package://Digital_twin_lab-2/meshes/gripper.STL" />
      </geometry>
      <material
        name="">
        <color
          rgba="0.752941176470588 0.752941176470588 0.752941176470588 1" />
      </material>
    </visual>
    <collision>
      <origin
        xyz="0 0 0"
        rpy="0 0 0" />
      <geometry>
        <mesh
          filename="package://Digital_twin_lab-2/meshes/gripper.STL" />
      </geometry>
    </collision>
  </link>
  <joint
    name="gripper-j"
    type="fixed">
    <origin
      xyz="-2.73703670415686 1.09480351822385 -0.0213981660270632"
      rpy="-1.57079632964652 -0.0165923813541522 -1.57079615491364" />
    <parent
      link="wrist2" />
    <child
      link="gripper" />
    <axis
      xyz="0 0 0" />
  </joint>
  <link
    name="squid1">
    <inertial>
      <origin
        xyz="0.00217519723344894 0.107745951384962 -0.0152297106388053"
        rpy="0 0 0" />
      <mass
        value="3.63619504672605" />
      <inertia
        ixx="0.0528314659485867"
        ixy="-3.98656771778607E-06"
        ixz="-0.000282892683176612"
        iyy="0.0673167761503227"
        iyz="6.61872461981687E-07"
        izz="0.0195251698514205" />
    </inertial>
    <visual>
      <origin
        xyz="0 0 0"
        rpy="0 0 0" />
      <geometry>
        <mesh
          filename="package://Digital_twin_lab-2/meshes/squid1.STL" />
      </geometry>
      <material
        name="">
        <color
          rgba="0.792156862745098 0.819607843137255 0.933333333333333 1" />
      </material>
    </visual>
    <collision>
      <origin
        xyz="0 0 0"
        rpy="0 0 0" />
      <geometry>
        <mesh
          filename="package://Digital_twin_lab-2/meshes/squid1.STL" />
      </geometry>
    </collision>
  </link>
  <joint
    name="squid-j"
    type="fixed">
    <origin
      xyz="-0.69586 -0.66731 0.059932"
      rpy="1.5708 0 3.1416" />
    <parent
      link="base_link" />
    <child
      link="squid1" />
    <axis
      xyz="0 0 0" />
  </joint>
  <link
    name="microplate_incubator">
    <inertial>
      <origin
        xyz="-0.166432525066334 0.314375603156406 -0.182353009501486"
        rpy="0 0 0" />
      <mass
        value="4.15140484031969" />
      <inertia
        ixx="0.0412959434046891"
        ixy="-2.28349994456826E-06"
        ixz="2.87903526488927E-05"
        iyy="0.0175131319455678"
        iyz="9.74814592294234E-05"
        izz="0.039296810124074" />
    </inertial>
    <visual>
      <origin
        xyz="0 0 0"
        rpy="0 0 0" />
      <geometry>
        <mesh
          filename="package://Digital_twin_lab-2/meshes/microplate_incubator.STL" />
      </geometry>
      <material
        name="">
        <color
          rgba="0.792156862745098 0.819607843137255 0.933333333333333 1" />
      </material>
    </visual>
    <collision>
      <origin
        xyz="0 0 0"
        rpy="0 0 0" />
      <geometry>
        <mesh
          filename="package://Digital_twin_lab-2/meshes/microplate_incubator.STL" />
      </geometry>
    </collision>
  </link>
  <joint
    name="microplate_incubator-j"
    type="fixed">
    <origin
      xyz="-0.032512 -0.82567 0.0612"
      rpy="1.5708 0 0" />
    <parent
      link="base_link" />
    <child
      link="microplate_incubator" />
    <axis
      xyz="0 0 0" />
  </joint>
  <link
    name="1">
    <inertial>
      <origin
        xyz="7.0532832383785E-05 4.59589526852211E-05 -0.00753805993131684"
        rpy="0 0 0" />
      <mass
        value="0.0868244944825263" />
      <inertia
        ixx="5.64144498466678E-05"
        ixy="2.40742980191029E-07"
        ixz="1.27388068981696E-08"
        iyy="0.000126271352614738"
        iyz="8.29625367427315E-09"
        izz="0.000180549328693109" />
    </inertial>
    <visual>
      <origin
        xyz="0 0 0"
        rpy="0 0 0" />
      <geometry>
        <mesh
          filename="package://Digital_twin_lab-2/meshes/1.STL" />
      </geometry>
      <material
        name="">
        <color
          rgba="1 1 1 1" />
      </material>
    </visual>
    <collision>
      <origin
        xyz="0 0 0"
        rpy="0 0 0" />
      <geometry>
        <mesh
          filename="package://Digital_twin_lab-2/meshes/1.STL" />
      </geometry>
    </collision>
  </link>
  <joint
    name="1j"
    type="fixed">
    <origin
      xyz="-0.14606 -0.68319 0.46012"
      rpy="3.1416 0 1.5708" />
    <parent
      link="base_link" />
    <child
      link="1" />
    <axis
      xyz="0 0 0" />
  </joint>
  <link
    name="2">
    <inertial>
      <origin
        xyz="7.0532832383785E-05 4.59589526852766E-05 -0.00753805993131679"
        rpy="0 0 0" />
      <mass
        value="0.0868244944825262" />
      <inertia
        ixx="5.64144498466677E-05"
        ixy="2.40742980191022E-07"
        ixz="1.27388068981685E-08"
        iyy="0.000126271352614738"
        iyz="8.29625367428312E-09"
        izz="0.000180549328693109" />
    </inertial>
    <visual>
      <origin
        xyz="0 0 0"
        rpy="0 0 0" />
      <geometry>
        <mesh
          filename="package://Digital_twin_lab-2/meshes/2.STL" />
      </geometry>
      <material
        name="">
        <color
          rgba="1 1 1 1" />
      </material>
    </visual>
    <collision>
      <origin
        xyz="0 0 0"
        rpy="0 0 0" />
      <geometry>
        <mesh
          filename="package://Digital_twin_lab-2/meshes/2.STL" />
      </geometry>
    </collision>
  </link>
  <joint
    name="2j"
    type="fixed">
    <origin
      xyz="-0.25543 -0.68319 0.46012"
      rpy="3.1416 0 1.5708" />
    <parent
      link="base_link" />
    <child
      link="2" />
    <axis
      xyz="0 0 0" />
  </joint>
  <link
    name="3">
    <inertial>
      <origin
        xyz="7.0532832383785E-05 4.59589526852211E-05 -0.00753805993131673"
        rpy="0 0 0" />
      <mass
        value="0.0868244944825262" />
      <inertia
        ixx="5.64144498466678E-05"
        ixy="2.40742980191027E-07"
        ixz="1.27388068981704E-08"
        iyy="0.000126271352614738"
        iyz="8.29625367427234E-09"
        izz="0.000180549328693109" />
    </inertial>
    <visual>
      <origin
        xyz="0 0 0"
        rpy="0 0 0" />
      <geometry>
        <mesh
          filename="package://Digital_twin_lab-2/meshes/3.STL" />
      </geometry>
      <material
        name="">
        <color
          rgba="1 1 1 1" />
      </material>
    </visual>
    <collision>
      <origin
        xyz="0 0 0"
        rpy="0 0 0" />
      <geometry>
        <mesh
          filename="package://Digital_twin_lab-2/meshes/3.STL" />
      </geometry>
    </collision>
  </link>
  <joint
    name="3j"
    type="fixed">
    <origin
      xyz="-0.14606 -0.68319 0.42998"
      rpy="3.1416 0 1.5708" />
    <parent
      link="base_link" />
    <child
      link="3" />
    <axis
      xyz="0 0 0" />
  </joint>
  <link
    name="4">
    <inertial>
      <origin
        xyz="7.05328323838961E-05 4.59589526852766E-05 -0.00753805993131673"
        rpy="0 0 0" />
      <mass
        value="0.0868244944825262" />
      <inertia
        ixx="5.64144498466677E-05"
        ixy="2.40742980191021E-07"
        ixz="1.27388068981687E-08"
        iyy="0.000126271352614738"
        iyz="8.29625367428251E-09"
        izz="0.000180549328693109" />
    </inertial>
    <visual>
      <origin
        xyz="0 0 0"
        rpy="0 0 0" />
      <geometry>
        <mesh
          filename="package://Digital_twin_lab-2/meshes/4.STL" />
      </geometry>
      <material
        name="">
        <color
          rgba="1 1 1 1" />
      </material>
    </visual>
    <collision>
      <origin
        xyz="0 0 0"
        rpy="0 0 0" />
      <geometry>
        <mesh
          filename="package://Digital_twin_lab-2/meshes/4.STL" />
      </geometry>
    </collision>
  </link>
  <joint
    name="4j"
    type="fixed">
    <origin
      xyz="-0.25543 -0.68319 0.42998"
      rpy="3.1416 0 1.5708" />
    <parent
      link="base_link" />
    <child
      link="4" />
    <axis
      xyz="0 0 0" />
  </joint>
  <link
    name="5">
    <inertial>
      <origin
        xyz="7.0532832383785E-05 4.59589526852211E-05 -0.00753805993131679"
        rpy="0 0 0" />
      <mass
        value="0.0868244944825262" />
      <inertia
        ixx="5.64144498466678E-05"
        ixy="2.40742980191027E-07"
        ixz="1.27388068981695E-08"
        iyy="0.000126271352614738"
        iyz="8.29625367427322E-09"
        izz="0.000180549328693109" />
    </inertial>
    <visual>
      <origin
        xyz="0 0 0"
        rpy="0 0 0" />
      <geometry>
        <mesh
          filename="package://Digital_twin_lab-2/meshes/5.STL" />
      </geometry>
      <material
        name="">
        <color
          rgba="1 1 1 1" />
      </material>
    </visual>
    <collision>
      <origin
        xyz="0 0 0"
        rpy="0 0 0" />
      <geometry>
        <mesh
          filename="package://Digital_twin_lab-2/meshes/5.STL" />
      </geometry>
    </collision>
  </link>
  <joint
    name="5j"
    type="fixed">
    <origin
      xyz="-0.14606 -0.68319 0.40006"
      rpy="3.1416 0 1.5708" />
    <parent
      link="base_link" />
    <child
      link="5" />
    <axis
      xyz="0 0 0" />
  </joint>
  <link
    name="6">
    <inertial>
      <origin
        xyz="7.0532832383785E-05 4.59589526852766E-05 -0.00753805993131679"
        rpy="0 0 0" />
      <mass
        value="0.0868244944825262" />
      <inertia
        ixx="5.64144498466677E-05"
        ixy="2.40742980191022E-07"
        ixz="1.27388068981684E-08"
        iyy="0.000126271352614738"
        iyz="8.29625367428299E-09"
        izz="0.000180549328693109" />
    </inertial>
    <visual>
      <origin
        xyz="0 0 0"
        rpy="0 0 0" />
      <geometry>
        <mesh
          filename="package://Digital_twin_lab-2/meshes/6.STL" />
      </geometry>
      <material
        name="">
        <color
          rgba="1 1 1 1" />
      </material>
    </visual>
    <collision>
      <origin
        xyz="0 0 0"
        rpy="0 0 0" />
      <geometry>
        <mesh
          filename="package://Digital_twin_lab-2/meshes/6.STL" />
      </geometry>
    </collision>
  </link>
  <joint
    name="6j"
    type="fixed">
    <origin
      xyz="-0.25543 -0.68319 0.40006"
      rpy="3.1416 0 1.5708" />
    <parent
      link="base_link" />
    <child
      link="6" />
    <axis
      xyz="0 0 0" />
  </joint>
  <link
    name="7">
    <inertial>
      <origin
        xyz="7.0532832383785E-05 4.59589526852211E-05 -0.00753805993131679"
        rpy="0 0 0" />
      <mass
        value="0.0868244944825263" />
      <inertia
        ixx="5.64144498466678E-05"
        ixy="2.40742980191027E-07"
        ixz="1.27388068981694E-08"
        iyy="0.000126271352614738"
        iyz="8.29625367427315E-09"
        izz="0.000180549328693109" />
    </inertial>
    <visual>
      <origin
        xyz="0 0 0"
        rpy="0 0 0" />
      <geometry>
        <mesh
          filename="package://Digital_twin_lab-2/meshes/7.STL" />
      </geometry>
      <material
        name="">
        <color
          rgba="1 1 1 1" />
      </material>
    </visual>
    <collision>
      <origin
        xyz="0 0 0"
        rpy="0 0 0" />
      <geometry>
        <mesh
          filename="package://Digital_twin_lab-2/meshes/7.STL" />
      </geometry>
    </collision>
  </link>
  <joint
    name="7j"
    type="fixed">
    <origin
      xyz="-0.14606 -0.68319 0.37007"
      rpy="3.1416 0 1.5708" />
    <parent
      link="base_link" />
    <child
      link="7" />
    <axis
      xyz="0 0 0" />
  </joint>
  <link
    name="8">
    <inertial>
      <origin
        xyz="7.05328323838961E-05 4.59589526852766E-05 -0.00753805993131668"
        rpy="0 0 0" />
      <mass
        value="0.0868244944825262" />
      <inertia
        ixx="5.64144498466677E-05"
        ixy="2.4074298019102E-07"
        ixz="1.27388068981686E-08"
        iyy="0.000126271352614738"
        iyz="8.29625367428301E-09"
        izz="0.000180549328693109" />
    </inertial>
    <visual>
      <origin
        xyz="0 0 0"
        rpy="0 0 0" />
      <geometry>
        <mesh
          filename="package://Digital_twin_lab-2/meshes/8.STL" />
      </geometry>
      <material
        name="">
        <color
          rgba="1 1 1 1" />
      </material>
    </visual>
    <collision>
      <origin
        xyz="0 0 0"
        rpy="0 0 0" />
      <geometry>
        <mesh
          filename="package://Digital_twin_lab-2/meshes/8.STL" />
      </geometry>
    </collision>
  </link>
  <joint
    name="8j"
    type="fixed">
    <origin
      xyz="-0.25543 -0.68319 0.37007"
      rpy="3.1416 0 1.5708" />
    <parent
      link="base_link" />
    <child
      link="8" />
    <axis
      xyz="0 0 0" />
  </joint>
  <link
    name="9">
    <inertial>
      <origin
        xyz="7.05328323838961E-05 4.59589526852489E-05 -0.00753805993131679"
        rpy="0 0 0" />
      <mass
        value="0.0868244944825262" />
      <inertia
        ixx="5.64144498466678E-05"
        ixy="2.40742980191028E-07"
        ixz="1.27388068981704E-08"
        iyy="0.000126271352614738"
        iyz="8.29625367427228E-09"
        izz="0.000180549328693109" />
    </inertial>
    <visual>
      <origin
        xyz="0 0 0"
        rpy="0 0 0" />
      <geometry>
        <mesh
          filename="package://Digital_twin_lab-2/meshes/9.STL" />
      </geometry>
      <material
        name="">
        <color
          rgba="1 1 1 1" />
      </material>
    </visual>
    <collision>
      <origin
        xyz="0 0 0"
        rpy="0 0 0" />
      <geometry>
        <mesh
          filename="package://Digital_twin_lab-2/meshes/9.STL" />
      </geometry>
    </collision>
  </link>
  <joint
    name="9j"
    type="fixed">
    <origin
      xyz="-0.14606 -0.68319 0.34023"
      rpy="3.1416 0 1.5708" />
    <parent
      link="base_link" />
    <child
      link="9" />
    <axis
      xyz="0 0 0" />
  </joint>
  <link
    name="10">
    <inertial>
      <origin
        xyz="7.05328323838961E-05 4.59589526852766E-05 -0.00753805993131673"
        rpy="0 0 0" />
      <mass
        value="0.0868244944825262" />
      <inertia
        ixx="5.64144498466677E-05"
        ixy="2.40742980191022E-07"
        ixz="1.27388068981689E-08"
        iyy="0.000126271352614738"
        iyz="8.29625367428243E-09"
        izz="0.000180549328693109" />
    </inertial>
    <visual>
      <origin
        xyz="0 0 0"
        rpy="0 0 0" />
      <geometry>
        <mesh
          filename="package://Digital_twin_lab-2/meshes/10.STL" />
      </geometry>
      <material
        name="">
        <color
          rgba="1 1 1 1" />
      </material>
    </visual>
    <collision>
      <origin
        xyz="0 0 0"
        rpy="0 0 0" />
      <geometry>
        <mesh
          filename="package://Digital_twin_lab-2/meshes/10.STL" />
      </geometry>
    </collision>
  </link>
  <joint
    name="10j"
    type="fixed">
    <origin
      xyz="-0.25543 -0.68319 0.34023"
      rpy="3.1416 0 1.5708" />
    <parent
      link="base_link" />
    <child
      link="10" />
    <axis
      xyz="0 0 0" />
  </joint>
  <link
    name="11">
    <inertial>
      <origin
        xyz="7.0532832383785E-05 4.59589526852211E-05 -0.00753805993131679"
        rpy="0 0 0" />
      <mass
        value="0.0868244944825263" />
      <inertia
        ixx="5.64144498466678E-05"
        ixy="2.40742980191028E-07"
        ixz="1.27388068981695E-08"
        iyy="0.000126271352614738"
        iyz="8.29625367427332E-09"
        izz="0.000180549328693109" />
    </inertial>
    <visual>
      <origin
        xyz="0 0 0"
        rpy="0 0 0" />
      <geometry>
        <mesh
          filename="package://Digital_twin_lab-2/meshes/11.STL" />
      </geometry>
      <material
        name="">
        <color
          rgba="1 1 1 1" />
      </material>
    </visual>
    <collision>
      <origin
        xyz="0 0 0"
        rpy="0 0 0" />
      <geometry>
        <mesh
          filename="package://Digital_twin_lab-2/meshes/11.STL" />
      </geometry>
    </collision>
  </link>
  <joint
    name="11j"
    type="fixed">
    <origin
      xyz="-0.14606 -0.68319 0.31009"
      rpy="3.1416 0 1.5708" />
    <parent
      link="base_link" />
    <child
      link="11" />
    <axis
      xyz="0 0 0" />
  </joint>
  <link
    name="12">
    <inertial>
      <origin
        xyz="7.0532832383785E-05 4.59589526852766E-05 -0.00753805993131679"
        rpy="0 0 0" />
      <mass
        value="0.0868244944825262" />
      <inertia
        ixx="5.64144498466677E-05"
        ixy="2.40742980191022E-07"
        ixz="1.27388068981683E-08"
        iyy="0.000126271352614738"
        iyz="8.29625367428308E-09"
        izz="0.000180549328693109" />
    </inertial>
    <visual>
      <origin
        xyz="0 0 0"
        rpy="0 0 0" />
      <geometry>
        <mesh
          filename="package://Digital_twin_lab-2/meshes/12.STL" />
      </geometry>
      <material
        name="">
        <color
          rgba="1 1 1 1" />
      </material>
    </visual>
    <collision>
      <origin
        xyz="0 0 0"
        rpy="0 0 0" />
      <geometry>
        <mesh
          filename="package://Digital_twin_lab-2/meshes/12.STL" />
      </geometry>
    </collision>
  </link>
  <joint
    name="12j"
    type="fixed">
    <origin
      xyz="-0.25543 -0.68319 0.31009"
      rpy="3.1416 0 1.5708" />
    <parent
      link="base_link" />
    <child
      link="12" />
    <axis
      xyz="0 0 0" />
  </joint>
  <link
    name="13">
    <inertial>
      <origin
        xyz="7.0532832383785E-05 4.59589526852211E-05 -0.00753805993131679"
        rpy="0 0 0" />
      <mass
        value="0.0868244944825262" />
      <inertia
        ixx="5.64144498466678E-05"
        ixy="2.40742980191027E-07"
        ixz="1.27388068981704E-08"
        iyy="0.000126271352614738"
        iyz="8.29625367427233E-09"
        izz="0.000180549328693109" />
    </inertial>
    <visual>
      <origin
        xyz="0 0 0"
        rpy="0 0 0" />
      <geometry>
        <mesh
          filename="package://Digital_twin_lab-2/meshes/13.STL" />
      </geometry>
      <material
        name="">
        <color
          rgba="1 1 1 1" />
      </material>
    </visual>
    <collision>
      <origin
        xyz="0 0 0"
        rpy="0 0 0" />
      <geometry>
        <mesh
          filename="package://Digital_twin_lab-2/meshes/13.STL" />
      </geometry>
    </collision>
  </link>
  <joint
    name="13j"
    type="fixed">
    <origin
      xyz="-0.14606 -0.68319 0.28017"
      rpy="3.1416 0 1.5708" />
    <parent
      link="base_link" />
    <child
      link="13" />
    <axis
      xyz="0 0 0" />
  </joint>
  <link
    name="14">
    <inertial>
      <origin
        xyz="7.05328323838961E-05 4.59589526852766E-05 -0.00753805993131679"
        rpy="0 0 0" />
      <mass
        value="0.0868244944825262" />
      <inertia
        ixx="5.64144498466677E-05"
        ixy="2.40742980191021E-07"
        ixz="1.27388068981687E-08"
        iyy="0.000126271352614738"
        iyz="8.2962536742823E-09"
        izz="0.000180549328693109" />
    </inertial>
    <visual>
      <origin
        xyz="0 0 0"
        rpy="0 0 0" />
      <geometry>
        <mesh
          filename="package://Digital_twin_lab-2/meshes/14.STL" />
      </geometry>
      <material
        name="">
        <color
          rgba="1 1 1 1" />
      </material>
    </visual>
    <collision>
      <origin
        xyz="0 0 0"
        rpy="0 0 0" />
      <geometry>
        <mesh
          filename="package://Digital_twin_lab-2/meshes/14.STL" />
      </geometry>
    </collision>
  </link>
  <joint
    name="14j"
    type="fixed">
    <origin
      xyz="-0.25543 -0.68319 0.28017"
      rpy="3.1416 0 1.5708" />
    <parent
      link="base_link" />
    <child
      link="14" />
    <axis
      xyz="0 0 0" />
  </joint>
  <link
    name="15">
    <inertial>
      <origin
        xyz="7.0532832383785E-05 4.59589526852211E-05 -0.00753805993131679"
        rpy="0 0 0" />
      <mass
        value="0.0868244944825262" />
      <inertia
        ixx="5.64144498466678E-05"
        ixy="2.40742980191027E-07"
        ixz="1.27388068981703E-08"
        iyy="0.000126271352614738"
        iyz="8.29625367427247E-09"
        izz="0.000180549328693109" />
    </inertial>
    <visual>
      <origin
        xyz="0 0 0"
        rpy="0 0 0" />
      <geometry>
        <mesh
          filename="package://Digital_twin_lab-2/meshes/15.STL" />
      </geometry>
      <material
        name="">
        <color
          rgba="1 1 1 1" />
      </material>
    </visual>
    <collision>
      <origin
        xyz="0 0 0"
        rpy="0 0 0" />
      <geometry>
        <mesh
          filename="package://Digital_twin_lab-2/meshes/15.STL" />
      </geometry>
    </collision>
  </link>
  <joint
    name="15j"
    type="fixed">
    <origin
      xyz="-0.14606 -0.68319 0.25018"
      rpy="3.1416 0 1.5708" />
    <parent
      link="base_link" />
    <child
      link="15" />
    <axis
      xyz="0 0 0" />
  </joint>
  <link
    name="16">
    <inertial>
      <origin
        xyz="7.0532832383785E-05 4.59589526852766E-05 -0.00753805993131679"
        rpy="0 0 0" />
      <mass
        value="0.0868244944825262" />
      <inertia
        ixx="5.64144498466677E-05"
        ixy="2.40742980191021E-07"
        ixz="1.27388068981687E-08"
        iyy="0.000126271352614738"
        iyz="8.2962536742825E-09"
        izz="0.000180549328693109" />
    </inertial>
    <visual>
      <origin
        xyz="0 0 0"
        rpy="0 0 0" />
      <geometry>
        <mesh
          filename="package://Digital_twin_lab-2/meshes/16.STL" />
      </geometry>
      <material
        name="">
        <color
          rgba="1 1 1 1" />
      </material>
    </visual>
    <collision>
      <origin
        xyz="0 0 0"
        rpy="0 0 0" />
      <geometry>
        <mesh
          filename="package://Digital_twin_lab-2/meshes/16.STL" />
      </geometry>
    </collision>
  </link>
  <joint
    name="16j"
    type="fixed">
    <origin
      xyz="-0.25543 -0.68319 0.25018"
      rpy="3.1416 0 1.5708" />
    <parent
      link="base_link" />
    <child
      link="16" />
    <axis
      xyz="0 0 0" />
  </joint>
  <link
    name="17">
    <inertial>
      <origin
        xyz="7.0532832383785E-05 4.59589526852489E-05 -0.00753805993131676"
        rpy="0 0 0" />
      <mass
        value="0.0868244944825262" />
      <inertia
        ixx="5.64144498466677E-05"
        ixy="2.40742980191031E-07"
        ixz="1.27388068981933E-08"
        iyy="0.000126271352614738"
        iyz="8.29625367427514E-09"
        izz="0.000180549328693109" />
    </inertial>
    <visual>
      <origin
        xyz="0 0 0"
        rpy="0 0 0" />
      <geometry>
        <mesh
          filename="package://Digital_twin_lab-2/meshes/17.STL" />
      </geometry>
      <material
        name="">
        <color
          rgba="1 1 1 1" />
      </material>
    </visual>
    <collision>
      <origin
        xyz="0 0 0"
        rpy="0 0 0" />
      <geometry>
        <mesh
          filename="package://Digital_twin_lab-2/meshes/17.STL" />
      </geometry>
    </collision>
  </link>
  <joint
    name="17j"
    type="fixed">
    <origin
      xyz="-0.14606 -0.68319 0.22026"
      rpy="3.1416 0 1.5708" />
    <parent
      link="base_link" />
    <child
      link="17" />
    <axis
      xyz="0 0 0" />
  </joint>
  <link
    name="18">
    <inertial>
      <origin
        xyz="7.05328323838961E-05 4.59589526852766E-05 -0.00753805993131676"
        rpy="0 0 0" />
      <mass
        value="0.0868244944825261" />
      <inertia
        ixx="5.64144498466676E-05"
        ixy="2.40742980191022E-07"
        ixz="1.27388068981917E-08"
        iyy="0.000126271352614738"
        iyz="8.29625367428528E-09"
        izz="0.000180549328693109" />
    </inertial>
    <visual>
      <origin
        xyz="0 0 0"
        rpy="0 0 0" />
      <geometry>
        <mesh
          filename="package://Digital_twin_lab-2/meshes/18.STL" />
      </geometry>
      <material
        name="">
        <color
          rgba="1 1 1 1" />
      </material>
    </visual>
    <collision>
      <origin
        xyz="0 0 0"
        rpy="0 0 0" />
      <geometry>
        <mesh
          filename="package://Digital_twin_lab-2/meshes/18.STL" />
      </geometry>
    </collision>
  </link>
  <joint
    name="18j"
    type="fixed">
    <origin
      xyz="-0.25543 -0.68319 0.22026"
      rpy="3.1416 0 1.5708" />
    <parent
      link="base_link" />
    <child
      link="18" />
    <axis
      xyz="0 0 0" />
  </joint>
  <link
    name="19">
    <inertial>
      <origin
        xyz="7.05328323838961E-05 4.59589526852489E-05 -0.00753805993131679"
        rpy="0 0 0" />
      <mass
        value="0.0868244944825262" />
      <inertia
        ixx="5.64144498466677E-05"
        ixy="2.40742980191031E-07"
        ixz="1.27388068981933E-08"
        iyy="0.000126271352614738"
        iyz="8.29625367427524E-09"
        izz="0.000180549328693109" />
    </inertial>
    <visual>
      <origin
        xyz="0 0 0"
        rpy="0 0 0" />
      <geometry>
        <mesh
          filename="package://Digital_twin_lab-2/meshes/19.STL" />
      </geometry>
      <material
        name="">
        <color
          rgba="1 1 1 1" />
      </material>
    </visual>
    <collision>
      <origin
        xyz="0 0 0"
        rpy="0 0 0" />
      <geometry>
        <mesh
          filename="package://Digital_twin_lab-2/meshes/19.STL" />
      </geometry>
    </collision>
  </link>
  <joint
    name="19j"
    type="fixed">
    <origin
      xyz="-0.14606 -0.68319 0.19034"
      rpy="3.1416 0 1.5708" />
    <parent
      link="base_link" />
    <child
      link="19" />
    <axis
      xyz="0 0 0" />
  </joint>
  <link
    name="20">
    <inertial>
      <origin
        xyz="7.05328323838961E-05 4.59589526852766E-05 -0.00753805993131676"
        rpy="0 0 0" />
      <mass
        value="0.0868244944825261" />
      <inertia
        ixx="5.64144498466676E-05"
        ixy="2.40742980191022E-07"
        ixz="1.27388068981918E-08"
        iyy="0.000126271352614738"
        iyz="8.29625367428514E-09"
        izz="0.000180549328693109" />
    </inertial>
    <visual>
      <origin
        xyz="0 0 0"
        rpy="0 0 0" />
      <geometry>
        <mesh
          filename="package://Digital_twin_lab-2/meshes/20.STL" />
      </geometry>
      <material
        name="">
        <color
          rgba="1 1 1 1" />
      </material>
    </visual>
    <collision>
      <origin
        xyz="0 0 0"
        rpy="0 0 0" />
      <geometry>
        <mesh
          filename="package://Digital_twin_lab-2/meshes/20.STL" />
      </geometry>
    </collision>
  </link>
  <joint
    name="20j"
    type="fixed">
    <origin
      xyz="-0.25543 -0.68319 0.19034"
      rpy="3.1416 0 1.5708" />
    <parent
      link="base_link" />
    <child
      link="20" />
    <axis
      xyz="0 0 0" />
  </joint>
  <link
    name="21">
    <inertial>
      <origin
        xyz="7.05328323838961E-05 4.59589526852489E-05 -0.00753805993131676"
        rpy="0 0 0" />
      <mass
        value="0.0868244944825262" />
      <inertia
        ixx="5.64144498466677E-05"
        ixy="2.40742980191031E-07"
        ixz="1.2738806898193E-08"
        iyy="0.000126271352614738"
        iyz="8.29625367427525E-09"
        izz="0.000180549328693109" />
    </inertial>
    <visual>
      <origin
        xyz="0 0 0"
        rpy="0 0 0" />
      <geometry>
        <mesh
          filename="package://Digital_twin_lab-2/meshes/21.STL" />
      </geometry>
      <material
        name="">
        <color
          rgba="1 1 1 1" />
      </material>
    </visual>
    <collision>
      <origin
        xyz="0 0 0"
        rpy="0 0 0" />
      <geometry>
        <mesh
          filename="package://Digital_twin_lab-2/meshes/21.STL" />
      </geometry>
    </collision>
  </link>
  <joint
    name="21j"
    type="fixed">
    <origin
      xyz="-0.14606 -0.68319 0.16035"
      rpy="3.1416 0 1.5708" />
    <parent
      link="base_link" />
    <child
      link="21" />
    <axis
      xyz="0 0 0" />
  </joint>
  <link
    name="22">
    <inertial>
      <origin
        xyz="7.05328323838961E-05 4.59589526852766E-05 -0.00753805993131676"
        rpy="0 0 0" />
      <mass
        value="0.0868244944825261" />
      <inertia
        ixx="5.64144498466676E-05"
        ixy="2.40742980191022E-07"
        ixz="1.27388068981918E-08"
        iyy="0.000126271352614737"
        iyz="8.29625367428527E-09"
        izz="0.000180549328693109" />
    </inertial>
    <visual>
      <origin
        xyz="0 0 0"
        rpy="0 0 0" />
      <geometry>
        <mesh
          filename="package://Digital_twin_lab-2/meshes/22.STL" />
      </geometry>
      <material
        name="">
        <color
          rgba="1 1 1 1" />
      </material>
    </visual>
    <collision>
      <origin
        xyz="0 0 0"
        rpy="0 0 0" />
      <geometry>
        <mesh
          filename="package://Digital_twin_lab-2/meshes/22.STL" />
      </geometry>
    </collision>
  </link>
  <joint
    name="22j"
    type="fixed">
    <origin
      xyz="-0.25543 -0.68319 0.16035"
      rpy="3.1416 0 1.5708" />
    <parent
      link="base_link" />
    <child
      link="22" />
    <axis
      xyz="0 0 0" />
  </joint>
  <link
    name="squid-plate">
    <inertial>
      <origin
        xyz="0 0 0"
        rpy="0 0 0" />
      <mass
        value="0" />
      <inertia
        ixx="0"
        ixy="0"
        ixz="0"
        iyy="0"
        iyz="0"
        izz="0" />
    </inertial>
    <visual>
      <origin
        xyz="0 0 0"
        rpy="0 0 0" />
      <geometry>
        <mesh
          filename="package://Digital_twin_lab-2/meshes/squid-plate.STL" />
      </geometry>
      <material
        name="">
        <color
          rgba="1 1 1 1" />
      </material>
    </visual>
    <collision>
      <origin
        xyz="0 0 0"
        rpy="0 0 0" />
      <geometry>
        <mesh
          filename="package://Digital_twin_lab-2/meshes/squid-plate.STL" />
      </geometry>
    </collision>
  </link>
  <joint
    name="squid-plate-j"
    type="fixed">
    <origin
      xyz="-0.737572080975208 -0.770270395471133 0.352632194611697"
      rpy="3.14159265358979 0 1.5707963267949" />
    <parent
      link="base_link" />
    <child
      link="squid-plate" />
    <axis
      xyz="0 0 0" />
  </joint>
</robot>