<?xml version="1.0" encoding="utf-8"?>
<!-- This URDF was automatically created by SolidWorks to URDF Exporter! Originally created by Stephen Brawner (brawner@gmail.com) 
     Commit Version: 1.6.0-4-g7f85cfe  Build Version: 1.6.7995.38578
     For more information, please see http://wiki.ros.org/sw_urdf_exporter -->
<robot
  name="SimulatedLab">
  <link
    name="OpticalTable">
    <inertial>
      <origin
        xyz="0.90651 -0.06459 1.1186"
        rpy="0 0 0" />
      <mass
        value="199.39" />
      <inertia
        ixx="10.566"
        ixy="2.822E-10"
        ixz="-1.278E-10"
        iyy="52.367"
        iyz="-7.1305E-12"
        izz="42.992" />
    </inertial>
    <visual>
      <origin
        xyz="0 0 0"
        rpy="0 0 0" />
      <geometry>
        <mesh
          filename="package://SimulatedLab/meshes/OpticalTable.STL" />
      </geometry>
      <material name="OpticalTableColor">
        <color rgba="0.8 0.8 0.8 1" />
      </material>
    </visual>
    <collision>
      <origin
        xyz="0 0 0"
        rpy="0 0 0" />
      <geometry>
        <mesh
          filename="package://SimulatedLab/meshes/OpticalTable.STL" />
      </geometry>
    </collision>
  </link>
  <link
    name="SlideRail">
    <inertial>
      <origin
        xyz="0.0092792 -0.043093 0.60802"
        rpy="0 0 0" />
      <mass
        value="9.3221" />
      <inertia
        ixx="7.2203"
        ixy="6.5868E-06"
        ixz="2.4777E-07"
        iyy="7.2215"
        iyz="-2.2278E-08"
        izz="0.0048847" />
    </inertial>
    <visual>
      <origin
        xyz="0 0 0"
        rpy="0 0 0" />
      <geometry>
        <mesh
          filename="package://SimulatedLab/meshes/SlideRail.STL" />
      </geometry>
      <material name="SlideRailColor">
        <color rgba="0.6 0.6 0.6 1" />
      </material>
    </visual>
    <collision>
      <origin
        xyz="0 0 0"
        rpy="0 0 0" />
      <geometry>
        <mesh
          filename="package://SimulatedLab/meshes/SlideRail.STL" />
      </geometry>
    </collision>
  </link>
  <joint
    name="rail-fix"
    type="fixed">
    <origin
      xyz="0.14169 -1.1751 0.052089"
      rpy="-1.5708 0 -1.5708" />
    <parent
      link="OpticalTable" />
    <child
      link="SlideRail" />
    <axis
      xyz="0 0 0" />
  </joint>
  <link
    name="SlideBrick">
    <inertial>
      <origin
        xyz="-0.0043089 0.040587 0.072566"
        rpy="0 0 0" />
      <mass
        value="0.41998" />
      <inertia
        ixx="0.00051075"
        ixy="1.166E-06"
        ixz="2.9612E-10"
        iyy="0.0010393"
        iyz="-1.1349E-09"
        izz="0.00060887" />
    </inertial>
    <visual>
      <origin
        xyz="0 0 0"
        rpy="0 0 0" />
      <geometry>
        <mesh
          filename="package://SimulatedLab/meshes/SlideBrick.STL" />
      </geometry>
      <material name="SlideBrickColor">
        <color rgba="0.7 0.7 0.7 1" />
      </material>
    </visual>
    <collision>
      <origin
        xyz="0 0 0"
        rpy="0 0 0" />
      <geometry>
        <mesh
          filename="package://SimulatedLab/meshes/SlideBrick.STL" />
      </geometry>
    </collision>
  </link>
  <joint
    name="Slide"
    type="prismatic">
    <origin
      xyz="0.0041396 -0.033447 -0.7972"
      rpy="3.1416 0 0" />
    <parent
      link="SlideRail" />
    <child
      link="SlideBrick" />
    <axis
      xyz="0 0 1" />
    <limit
      lower="-3.5"
      upper="0"
      effort="0"
      velocity="0" />
  </joint>
  <link
    name="Rail-Robot-connector">
    <inertial>
      <origin
        xyz="8.9813E-05 0.011003 -0.00012483"
        rpy="0 0 0" />
      <mass
        value="0.55039" />
      <inertia
        ixx="0.00066968"
        ixy="1.4513E-07"
        ixz="-1.9344E-06"
        iyy="0.0015558"
        iyz="-2.0364E-07"
        izz="0.00091884" />
    </inertial>
    <visual>
      <origin
        xyz="0 0 0"
        rpy="0 0 0" />
      <geometry>
        <mesh
          filename="package://SimulatedLab/meshes/Rail-Robot-connector.STL" />
      </geometry>
      <material name="DornaArmColor">
        <color rgba="0.1 0.5 0.8 1" />
      </material>
    </visual>

  </link>
  <joint
    name="Rail-Robot-connector-fix"
    type="fixed">
    <origin
      xyz="-0.0041396 0.055847 0.072641"
      rpy="0 1.5708 0" />
    <parent
      link="SlideBrick" />
    <child
      link="Rail-Robot-connector" />
    <axis
      xyz="0 0 0" />
  </joint>
  <link
    name="arm-base">
    <inertial>
      <origin
        xyz="-0.0013781 0.062393 -0.049951"
        rpy="0 0 0" />
      <mass
        value="0.17228" />
      <inertia
        ixx="8.7832E-05"
        ixy="1.6836E-07"
        ixz="2.0372E-07"
        iyy="0.00015376"
        iyz="5.3127E-07"
        izz="8.8824E-05" />
    </inertial>
    <visual>
      <origin
        xyz="0 0 0"
        rpy="0 0 0" />
      <geometry>
        <mesh
          filename="package://SimulatedLab/meshes/arm-base.STL" />
      </geometry>
      <material name="DornaArmColor">
        <color rgba="0.1 0.5 0.8 1" />
      </material>
    </visual>
    
    <collision>
      <origin
        xyz="0 0 0"
        rpy="0 0 0" />
      <geometry>
        <mesh
          filename="package://SimulatedLab/meshes/arm-base.STL" />
      </geometry>
    </collision>

  </link>
  <joint
    name="armbaseJ"
    type="fixed">
    <origin
      xyz="0.0019527 -0.0078131 0.051373"
      rpy="0 0 0" />
    <parent
      link="Rail-Robot-connector" />
    <child
      link="arm-base" />
    <axis
      xyz="0 0 0" />
  </joint>
  <link
    name="arm1">
    <inertial>
      <origin
        xyz="0.0068555 0.11306 -0.031936"
        rpy="0 0 0" />
      <mass
        value="0.67527" />
      <inertia
        ixx="0.0020205"
        ixy="2.1595E-06"
        ixz="-1.2854E-05"
        iyy="0.0019142"
        iyz="-0.00044896"
        izz="0.00084524" />
    </inertial>
    <visual>
      <origin
        xyz="0 0 0"
        rpy="0 0 0" />
      <geometry>
        <mesh
          filename="package://SimulatedLab/meshes/arm1.STL" />
      </geometry>
      <material name="DornaArmColor">
        <color rgba="0.1 0.5 0.8 1" />
      </material>
    </visual>
    <collision>
      <origin
        xyz="0 0 0"
        rpy="0 0 0" />
      <geometry>
        <mesh
          filename="package://SimulatedLab/meshes/arm1.STL" />
      </geometry>
    </collision>
  </link>
  <joint
    name="arm1J"
    type="revolute">
    <origin
      xyz="-0.0019527 0.047214 -0.051373"
      rpy="1.5708 -1.5708 -1.5708" />
    <parent
      link="arm-base" />
    <child
      link="arm1" />
    <axis
      xyz="0 1 0" />
    <limit
      lower="-180"
      upper="180"
      effort="0"
      velocity="0" />
  </joint>
  <link
    name="arm2">
    <inertial>
      <origin
        xyz="0.0093492 0.050968 -6.2717E-06"
        rpy="0 0 0" />
      <mass
        value="0.27168" />
      <inertia
        ixx="0.0013356"
        ixy="-1.0161E-08"
        ixz="1.0591E-11"
        iyy="0.00010987"
        iyz="-8.797E-09"
        izz="0.0012912" />
    </inertial>
    <visual>
      <origin
        xyz="0 0 0"
        rpy="0 0 0" />
      <geometry>
        <mesh
          filename="package://SimulatedLab/meshes/arm2.STL" />
      </geometry>
      <material name="DornaArmColor">
        <color rgba="0.1 0.5 0.8 1" />
      </material>
    </visual>

  </link>
  <joint
    name="arm2J"
    type="revolute">
    <origin
      xyz="0 0.19707 0.095476"
      rpy="-1.5675 0 0" />
    <parent
      link="arm1" />
    <child
      link="arm2" />
    <axis
      xyz="1 0 0" />
    <limit
      lower="-180"
      upper="180"
      effort="0"
      velocity="0" />
  </joint>
  <link
    name="arm3">
    <inertial>
      <origin
        xyz="-0.0034044 -5.1122E-06 0.03101"
        rpy="0 0 0" />
      <mass
        value="0.29344" />
      <inertia
        ixx="0.00057371"
        ixy="-3.2473E-09"
        ixz="2.2346E-06"
        iyy="0.00054217"
        iyz="3.7859E-09"
        izz="6.7363E-05" />
    </inertial>
    <visual>
      <origin
        xyz="0 0 0"
        rpy="0 0 0" />
      <geometry>
        <mesh
          filename="package://SimulatedLab/meshes/arm3.STL" />
      </geometry>
      <material name="DornaArmColor">
        <color rgba="0.1 0.5 0.8 1" />
      </material>
    </visual>

  </link>
  <joint
    name="arm3J"
    type="revolute">
    <origin
      xyz="0 0.2032 0"
      rpy="0.89363 0 0" />
    <parent
      link="arm2" />
    <child
      link="arm3" />
    <axis
      xyz="1 0 0" />
    <limit
      lower="-180"
      upper="180"
      effort="0"
      velocity="0" />
  </joint>
  <link
    name="wrist1">
    <inertial>
      <origin
        xyz="-5.1119E-05 5.5335E-07 3.3649E-05"
        rpy="0 0 0" />
      <mass
        value="0.019467" />
      <inertia
        ixx="1.9403E-06"
        ixy="-2.6043E-12"
        ixz="3.7257E-11"
        iyy="5.5184E-06"
        iyz="1.4992E-08"
        izz="6.4217E-06" />
    </inertial>
    <visual>
      <origin
        xyz="0 0 0"
        rpy="0 0 0" />
      <geometry>
        <mesh
          filename="package://SimulatedLab/meshes/wrist1.STL" />
      </geometry>
        <material name="DornaArmColor">
        <color rgba="0.1 0.5 0.8 1" />
      </material>
    </visual>
    <collision>
      <origin
        xyz="0 0 0"
        rpy="0 0 0" />
      <geometry>
        <mesh
          filename="package://SimulatedLab/meshes/wrist1.STL" />
      </geometry>
    </collision>
  </link>
  <joint
    name="arm-wrist"
    type="revolute">
    <origin
      xyz="0 0 0.1524"
      rpy="2.35 0 3.1416" />
    <parent
      link="arm3" />
    <child
      link="wrist1" />
    <axis
      xyz="1 0 0" />
    <limit
      lower="-180"
      upper="180"
      effort="0"
      velocity="0" />
  </joint>
  <link
    name="wrist2">
    <inertial>
      <origin
        xyz="-9.7487E-05 0.0011324 0.03436"
        rpy="0 0 0" />
      <mass
        value="0.010769" />
      <inertia
        ixx="3.7831E-06"
        ixy="-6.8973E-13"
        ixz="-2.093E-12"
        iyy="3.859E-06"
        iyz="-1.1375E-07"
        izz="8.956E-07" />
    </inertial>
    <visual>
      <origin
        xyz="0 0 0"
        rpy="0 0 0" />
      <geometry>
        <mesh
          filename="package://SimulatedLab/meshes/wrist2.STL" />
      </geometry>
      <material name="DornaArmColor">
        <color rgba="0.1 0.5 0.8 1" />
      </material>
    </visual>
    <collision>
      <origin
        xyz="0 0 0"
        rpy="0 0 0" />
      <geometry>
        <mesh
          filename="package://SimulatedLab/meshes/wrist2.STL" />
      </geometry>
    </collision>
  </link>
  <joint
    name="wrist2-j"
    type="revolute">
    <origin
      xyz="0 0 0"
      rpy="0 0 0" />
    <parent
      link="wrist1" />
    <child
      link="wrist2" />
    <axis
      xyz="0 0.016592 0.99986" />
    <limit
      lower="-180"
      upper="180"
      effort="0"
      velocity="0" />
    <mimic
      joint="arm1J"
      multiplier="1"
      offset="0" />
  </joint>
  <link
    name="SquidMicroscope">
    <inertial>
      <origin
        xyz="0.0005327 0.10804 -0.0085527"
        rpy="0 0 0" />
      <mass
        value="3.6417" />
      <inertia
        ixx="0.052832"
        ixy="-3.9904E-06"
        ixz="-0.00028322"
        iyy="0.067318"
        iyz="6.7962E-07"
        izz="0.019526" />
    </inertial>
    <visual>
      <origin
        xyz="0 0 0"
        rpy="0 0 0" />
      <geometry>
        <mesh
          filename="package://SimulatedLab/meshes/SquidMicroscope.STL" />
      </geometry>
     <material name="SquidMicroscopeColor">
        <color rgba="0.5 0.1 0.6 1" />
      </material>
    </visual>
    <collision>
      <origin
        xyz="0 0 0"
        rpy="0 0 0" />
      <geometry>
        <mesh
          filename="package://SimulatedLab/meshes/SquidMicroscope.STL" />
      </geometry>
    </collision>
  </link>
  <joint
    name="microscope-fix"
    type="fixed">
    <origin
      xyz="-0.073823 -0.66731 0.059932"
      rpy="1.5708 0 3.1416" />
    <parent
      link="OpticalTable" />
    <child
      link="SquidMicroscope" />
    <axis
      xyz="0 0 0" />
  </joint>
  <link
    name="MicroplateHolder">
    <inertial>
      <origin
        xyz="0 0 0"
        rpy="0 0 0" />
      <mass
        value="0" />
      <inertia
        ixx="0"
        ixy="0"
        ixz="0"
        iyy="0"
        iyz="0"
        izz="0" />
    </inertial>
    <visual>
      <origin
        xyz="0 0 0"
        rpy="0 0 0" />
      <geometry>
        <mesh
          filename="package://SimulatedLab/meshes/MicroplateHolder.STL" />
      </geometry>
      <material name="MicroplateHolderColor">
        <color rgba="0.9 0.8 0.1 1" />
      </material>
    </visual>
    <collision>
      <origin
        xyz="0 0 0"
        rpy="0 0 0" />
      <geometry>
        <mesh
          filename="package://SimulatedLab/meshes/MicroplateHolder.STL" />
      </geometry>
    </collision>
  </link>
  <joint
    name="hotel-fix"
    type="fixed">
    <origin
      xyz="0.818329937973544 -0.725482308658135 0.129836500776815"
      rpy="1.5707963267949 0 0" />
    <parent
      link="OpticalTable" />
    <child
      link="MicroplateHolder" />
    <axis
      xyz="0 0 0" />
  </joint>
</robot>