<?xml version="1.0" encoding="utf-8"?>
<!-- This URDF was automatically created by SolidWorks to URDF Exporter! Originally created by Stephen Brawner (brawner@gmail.com) 
     Commit Version: 1.6.0-4-g7f85cfe  Build Version: 1.6.7995.38578
     For more information, please see http://wiki.ros.org/sw_urdf_exporter -->
<robot
  name="SimulatedLab-urdf.SLDASM">
  <link
    name="base_link">
    <inertial>
      <origin
        xyz="0.653049682164994 0.306864386533706 0.21880478316424"
        rpy="0 0 0" />
      <mass
        value="462.943637851792" />
      <inertia
        ixx="36.0265418542219"
        ixy="0.00282870253677017"
        ixz="4.69489306138363E-10"
        iyy="76.7256657120753"
        iyz="-0.0348331755633981"
        izz="67.5997793901126" />
    </inertial>
    <visual>
      <origin
        xyz="0 0 0"
        rpy="0 0 0" />
      <geometry>
        <mesh
          filename="package://SimulatedLab-urdf.SLDASM/meshes/base_link.STL" />
      </geometry>
      <material
        name="">
        <color
          rgba="0.752941176470588 0.752941176470588 0.752941176470588 1" />
      </material>
    </visual>
    <collision>
      <origin
        xyz="0 0 0"
        rpy="0 0 0" />
      <geometry>
        <mesh
          filename="package://SimulatedLab-urdf.SLDASM/meshes/base_link.STL" />
      </geometry>
    </collision>
  </link>
  <link
    name="slide">
    <inertial>
      <origin
        xyz="-0.0726846938106485 0.0125920764345532 0.0264611703578577"
        rpy="0 0 0" />
      <mass
        value="1.14266042467365" />
      <inertia
        ixx="0.00136637515019257"
        ixy="1.73102113067279E-06"
        ixz="-3.14623442686402E-07"
        iyy="0.00151841225352388"
        iyz="1.49355511609002E-06"
        izz="0.00274882213327605" />
    </inertial>
    <visual>
      <origin
        xyz="0 0 0"
        rpy="0 0 0" />
      <geometry>
        <mesh
          filename="package://SimulatedLab-urdf.SLDASM/meshes/slide.STL" />
      </geometry>
      <material
        name="">
        <color
          rgba="1 1 1 1" />
      </material>
    </visual>
    <collision>
      <origin
        xyz="0 0 0"
        rpy="0 0 0" />
      <geometry>
        <mesh
          filename="package://SimulatedLab-urdf.SLDASM/meshes/slide.STL" />
      </geometry>
    </collision>
  </link>
  <joint
    name="slide-j"
    type="prismatic">
    <origin
      xyz="-1.5388 0.037454 0.0707"
      rpy="0 0 0" />
    <parent
      link="base_link" />
    <child
      link="slide" />
    <axis
      xyz="1 0 0" />
    <limit
      lower="0"
      upper="3.4"
      effort="0"
      velocity="0" />
  </joint>
  <link
    name="arm1">
    <inertial>
      <origin
        xyz="-0.0319364363545338 0.00685555878860736 0.113055730014538"
        rpy="0 0 0" />
      <mass
        value="0.675270731859802" />
      <inertia
        ixx="0.000845244393641282"
        ixy="-1.28545007551652E-05"
        ixz="-0.000448958588201122"
        iyy="0.00202049846117989"
        iyz="2.1595258421346E-06"
        izz="0.00191415491964012" />
    </inertial>
    <visual>
      <origin
        xyz="0 0 0"
        rpy="0 0 0" />
      <geometry>
        <mesh
          filename="package://SimulatedLab-urdf.SLDASM/meshes/arm1.STL" />
      </geometry>
      <material
        name="">
        <color
          rgba="0.792156862745098 0.819607843137255 0.933333333333333 1" />
      </material>
    </visual>
    <collision>
      <origin
        xyz="0 0 0"
        rpy="0 0 0" />
      <geometry>
        <mesh
          filename="package://SimulatedLab-urdf.SLDASM/meshes/arm1.STL" />
      </geometry>
    </collision>
  </link>
  <joint
    name="joint0"
    type="revolute">
    <origin
      xyz="-0.072527 0.0125 0.05791"
      rpy="0 0 0" />
    <parent
      link="slide" />
    <child
      link="arm1" />
    <axis
      xyz="0 0 1" />
    <limit
      lower="0"
      upper="0"
      effort="0"
      velocity="0" />
  </joint>
  <link
    name="arm2">
    <inertial>
      <origin
        xyz="0.0509684856633423 0.0153492189949184 6.26754704213806E-06"
        rpy="0 0 0" />
      <mass
        value="0.271676192230462" />
      <inertia
        ixx="0.000109874068210212"
        ixy="-1.01599128378266E-08"
        ixz="8.83219871803655E-09"
        iyy="0.00133562993036315"
        iyz="-1.82523903558782E-11"
        izz="0.00129117502224369" />
    </inertial>
    <visual>
      <origin
        xyz="0 0 0"
        rpy="0 0 0" />
      <geometry>
        <mesh
          filename="package://SimulatedLab-urdf.SLDASM/meshes/arm2.STL" />
      </geometry>
      <material
        name="">
        <color
          rgba="0.792156862745098 0.819607843137255 0.933333333333333 1" />
      </material>
    </visual>
    <collision>
      <origin
        xyz="0 0 0"
        rpy="0 0 0" />
      <geometry>
        <mesh
          filename="package://SimulatedLab-urdf.SLDASM/meshes/arm2.STL" />
      </geometry>
    </collision>
  </link>
  <joint
    name="joint1"
    type="revolute">
    <origin
      xyz="0.095476 0 0.19707"
      rpy="0 0 0" />
    <parent
      link="arm1" />
    <child
      link="arm2" />
    <axis
      xyz="0 1 0" />
    <limit
      lower="0"
      upper="0"
      effort="0"
      velocity="0" />
  </joint>
  <link
    name="arm3">
    <inertial>
      <origin
        xyz="0.03101 -0.0034044 -5.1127E-06"
        rpy="0 0 0" />
      <mass
        value="0.29344" />
      <inertia
        ixx="6.7363E-05"
        ixy="2.2346E-06"
        ixz="3.7979E-09"
        iyy="0.00057371"
        iyz="-3.2528E-09"
        izz="0.00054217" />
    </inertial>
    <visual>
      <origin
        xyz="0 0 0"
        rpy="0 0 0" />
      <geometry>
        <mesh
          filename="package://SimulatedLab-urdf.SLDASM/meshes/arm3.STL" />
      </geometry>
      <material
        name="">
        <color
          rgba="0.79216 0.81961 0.93333 1" />
      </material>
    </visual>
    <collision>
      <origin
        xyz="0 0 0"
        rpy="0 0 0" />
      <geometry>
        <mesh
          filename="package://SimulatedLab-urdf.SLDASM/meshes/arm3.STL" />
      </geometry>
    </collision>
  </link>
  <joint
    name="joint2"
    type="revolute">
    <origin
      xyz="0.2032 0 0"
      rpy="0 0 0" />
    <parent
      link="arm2" />
    <child
      link="arm3" />
    <axis
      xyz="0 1 0" />
    <limit
      lower="0"
      upper="0"
      effort="0"
      velocity="0" />
  </joint>
  <link
    name="wrist1">
    <inertial>
      <origin
        xyz="3.36531717246569E-05 5.11195832334846E-05 4.9986722538975E-09"
        rpy="0 0 0" />
      <mass
        value="0.0194666574215231" />
      <inertia
        ixx="6.42191931699274E-06"
        ixy="-3.72087128316696E-11"
        ixz="4.93307640481161E-13"
        iyy="1.94033958382307E-06"
        iyz="-2.6062453174593E-12"
        izz="5.51817407527833E-06" />
    </inertial>
    <visual>
      <origin
        xyz="0 0 0"
        rpy="0 0 0" />
      <geometry>
        <mesh
          filename="package://SimulatedLab-urdf.SLDASM/meshes/wrist1.STL" />
      </geometry>
      <material
        name="">
        <color
          rgba="0.792156862745098 0.819607843137255 0.933333333333333 1" />
      </material>
    </visual>
    <collision>
      <origin
        xyz="0 0 0"
        rpy="0 0 0" />
      <geometry>
        <mesh
          filename="package://SimulatedLab-urdf.SLDASM/meshes/wrist1.STL" />
      </geometry>
    </collision>
  </link>
  <joint
    name="joint3"
    type="revolute">
    <origin
      xyz="0.1524 0 0"
      rpy="0 0 0" />
    <parent
      link="arm3" />
    <child
      link="wrist1" />
    <axis
      xyz="0 1 0" />
    <limit
      lower="0"
      upper="0"
      effort="0"
      velocity="0" />
  </joint>
  <link
    name="wrist2">
    <inertial>
      <origin
        xyz="0.034220241357386 9.54482608361909E-05 0.00943650593940792"
        rpy="0 0 0" />
      <mass
        value="0.0107694009379911" />
      <inertia
        ixx="8.92646368872265E-07"
        ixy="2.36288667600708E-10"
        ixz="6.45243882520287E-08"
        iyy="3.78310290086787E-06"
        iyz="2.85442227236289E-10"
        izz="3.86192979090647E-06" />
    </inertial>
    <visual>
      <origin
        xyz="0 0 0"
        rpy="0 0 0" />
      <geometry>
        <mesh
          filename="package://SimulatedLab-urdf.SLDASM/meshes/wrist2.STL" />
      </geometry>
      <material
        name="">
        <color
          rgba="0.792156862745098 0.819607843137255 0.933333333333333 1" />
      </material>
    </visual>
    <collision>
      <origin
        xyz="0 0 0"
        rpy="0 0 0" />
      <geometry>
        <mesh
          filename="package://SimulatedLab-urdf.SLDASM/meshes/wrist2.STL" />
      </geometry>
    </collision>
  </link>
  <joint
    name="joint4"
    type="revolute">
    <origin
      xyz="0.00016592 0 -0.0099986"
      rpy="0 0 0" />
    <parent
      link="wrist1" />
    <child
      link="wrist2" />
    <axis
      xyz="1 0 0" />
    <limit
      lower="0"
      upper="0"
      effort="0"
      velocity="0" />
  </joint>
  <link
    name="gripper">
    <inertial>
      <origin
        xyz="0.00949183705309564 -0.0486045136797698 0.0239498763271673"
        rpy="0 0 0" />
      <mass
        value="1.24999140479793" />
      <inertia
        ixx="0.000270267300453715"
        ixy="1.45363492796375E-06"
        ixz="-3.1469385810925E-06"
        iyy="0.00026922690617649"
        iyz="4.10887677291944E-07"
        izz="0.000340538302381578" />
    </inertial>
    <visual>
      <origin
        xyz="0 0 0"
        rpy="0 0 0" />
      <geometry>
        <mesh
          filename="package://SimulatedLab-urdf.SLDASM/meshes/gripper.STL" />
      </geometry>
      <material
        name="">
        <color
          rgba="0.752941176470588 0.752941176470588 0.752941176470588 1" />
      </material>
    </visual>
    <collision>
      <origin
        xyz="0 0 0"
        rpy="0 0 0" />
      <geometry>
        <mesh
          filename="package://SimulatedLab-urdf.SLDASM/meshes/gripper.STL" />
      </geometry>
    </collision>
  </link>
  <joint
    name="gripper-j"
    type="fixed">
    <origin
      xyz="0.0496985837996879 3.98848680221997E-05 -0.00587627196529533"
      rpy="0 0 0" />
    <parent
      link="wrist2" />
    <child
      link="gripper" />
    <axis
      xyz="0 0 0" />
  </joint>
  <link
    name="plate-incubator">
    <inertial>
      <origin
        xyz="-4.5959E-05 -7.0533E-05 0.0075381"
        rpy="0 0 0" />
      <mass
        value="0.086824" />
      <inertia
        ixx="0.00012627"
        ixy="2.4074E-07"
        ixz="8.2963E-09"
        iyy="5.6414E-05"
        iyz="1.2739E-08"
        izz="0.00018055" />
    </inertial>
    <visual>
      <origin
        xyz="0 0 0"
        rpy="0 0 0" />
      <geometry>
        <mesh
          filename="package://SimulatedLab-urdf.SLDASM/meshes/plate-incubator.STL" />
      </geometry>
      <material
        name="">
        <color
          rgba="1 1 1 1" />
      </material>
    </visual>
    <collision>
      <origin
        xyz="0 0 0"
        rpy="0 0 0" />
      <geometry>
        <mesh
          filename="package://SimulatedLab-urdf.SLDASM/meshes/plate-incubator.STL" />
      </geometry>
    </collision>
  </link>
  <joint
    name="plate-incubator-j"
    type="fixed">
    <origin
      xyz="1.4197 0.33999 0.26826"
      rpy="0 0 0" />
    <parent
      link="base_link" />
    <child
      link="plate-incubator" />
    <axis
      xyz="0 0 0" />
  </joint>
  <link
    name="plate-microscope">
    <inertial>
      <origin
        xyz="0 0 0"
        rpy="0 0 0" />
      <mass
        value="0" />
      <inertia
        ixx="0"
        ixy="0"
        ixz="0"
        iyy="0"
        iyz="0"
        izz="0" />
    </inertial>
    <visual>
      <origin
        xyz="0 0 0"
        rpy="0 0 0" />
      <geometry>
        <mesh
          filename="package://SimulatedLab-urdf.SLDASM/meshes/plate-microscope.STL" />
      </geometry>
      <material
        name="">
        <color
          rgba="1 1 1 1" />
      </material>
    </visual>
    <collision>
      <origin
        xyz="0 0 0"
        rpy="0 0 0" />
      <geometry>
        <mesh
          filename="package://SimulatedLab-urdf.SLDASM/meshes/plate-microscope.STL" />
      </geometry>
    </collision>
  </link>
  <joint
    name="plate-microscope-j"
    type="fixed">
    <origin
      xyz="0.89452 0.40325 0.2996"
      rpy="0 0 0" />
    <parent
      link="base_link" />
    <child
      link="plate-microscope" />
    <axis
      xyz="0 0 0" />
  </joint>
</robot>